2025-04-27 15:47:00,610 INFO    StreamThr :22968 [internal.py:wandb_internal():86] W&B internal server running at pid: 22968, started at: 2025-04-27 15:47:00.609267
2025-04-27 15:47:00,611 DEBUG   HandlerThread:22968 [handler.py:handle_request():146] handle_request: status
2025-04-27 15:47:00,619 INFO    WriterThread:22968 [datastore.py:open_for_write():85] open: D:\IIT Delhi\Projects\Adversarial games\Experimentation\codeBase\wandb\run-20250427_154700-juanycn7\run-juanycn7.wandb
2025-04-27 15:47:00,619 DEBUG   SenderThread:22968 [sender.py:send():382] send: header
2025-04-27 15:47:00,658 DEBUG   SenderThread:22968 [sender.py:send():382] send: run
2025-04-27 15:47:01,460 ERROR   SenderThread:22968 [internal_api.py:execute():373] 403 response executing GraphQL.
2025-04-27 15:47:01,462 ERROR   SenderThread:22968 [internal_api.py:execute():374] {"errors":[{"message":"permission denied","path":["upsertBucket"],"extensions":{"code":"PERMISSION_ERROR"}}],"data":{"upsertBucket":null}}
2025-04-27 15:47:01,468 ERROR   SenderThread:22968 [sender.py:send_run():987] It appears that you do not have permission to access the requested resource. Please reach out to the project owner to grant you access. If you have the correct permissions, verify that there are no issues with your networking setup.(Error 403: Forbidden)
Traceback (most recent call last):
  File "C:\Users\ASUS\anaconda3\envs\gpu_torch_5\Lib\site-packages\wandb\sdk\lib\retry.py", line 131, in __call__
    result = self._call_fn(*args, **kwargs)
             ^^^^^^^^^^^^^^^^^^^^^^^^^^^^^^
  File "C:\Users\ASUS\anaconda3\envs\gpu_torch_5\Lib\site-packages\wandb\sdk\internal\internal_api.py", line 369, in execute
    return self.client.execute(*args, **kwargs)  # type: ignore
           ^^^^^^^^^^^^^^^^^^^^^^^^^^^^^^^^^^^^
  File "C:\Users\ASUS\anaconda3\envs\gpu_torch_5\Lib\site-packages\wandb\vendor\gql-0.2.0\wandb_gql\client.py", line 52, in execute
    result = self._get_result(document, *args, **kwargs)
             ^^^^^^^^^^^^^^^^^^^^^^^^^^^^^^^^^^^^^^^^^^^
  File "C:\Users\ASUS\anaconda3\envs\gpu_torch_5\Lib\site-packages\wandb\vendor\gql-0.2.0\wandb_gql\client.py", line 60, in _get_result
    return self.transport.execute(document, *args, **kwargs)
           ^^^^^^^^^^^^^^^^^^^^^^^^^^^^^^^^^^^^^^^^^^^^^^^^^
  File "C:\Users\ASUS\anaconda3\envs\gpu_torch_5\Lib\site-packages\wandb\sdk\lib\gql_request.py", line 59, in execute
    request.raise_for_status()
  File "C:\Users\ASUS\anaconda3\envs\gpu_torch_5\Lib\site-packages\requests\models.py", line 1024, in raise_for_status
    raise HTTPError(http_error_msg, response=self)
requests.exceptions.HTTPError: 403 Client Error: Forbidden for url: https://api.wandb.ai/graphql

During handling of the above exception, another exception occurred:

Traceback (most recent call last):
  File "C:\Users\ASUS\anaconda3\envs\gpu_torch_5\Lib\site-packages\wandb\sdk\internal\sender.py", line 985, in send_run
    self._init_run(run, config_value_dict)
  File "C:\Users\ASUS\anaconda3\envs\gpu_torch_5\Lib\site-packages\wandb\sdk\internal\sender.py", line 1027, in _init_run
    server_run, inserted, server_messages = self._api.upsert_run(
                                            ^^^^^^^^^^^^^^^^^^^^^
  File "C:\Users\ASUS\anaconda3\envs\gpu_torch_5\Lib\site-packages\wandb\apis\normalize.py", line 73, in wrapper
    raise err
  File "C:\Users\ASUS\anaconda3\envs\gpu_torch_5\Lib\site-packages\wandb\apis\normalize.py", line 41, in wrapper
    return func(*args, **kwargs)
           ^^^^^^^^^^^^^^^^^^^^^
  File "C:\Users\ASUS\anaconda3\envs\gpu_torch_5\Lib\site-packages\wandb\sdk\internal\internal_api.py", line 2212, in upsert_run
    response = self.gql(
               ^^^^^^^^^
  File "C:\Users\ASUS\anaconda3\envs\gpu_torch_5\Lib\site-packages\wandb\sdk\internal\internal_api.py", line 341, in gql
    ret = self._retry_gql(
          ^^^^^^^^^^^^^^^^
  File "C:\Users\ASUS\anaconda3\envs\gpu_torch_5\Lib\site-packages\wandb\sdk\lib\retry.py", line 147, in __call__
    retry_timedelta_triggered = check_retry_fn(e)
                                ^^^^^^^^^^^^^^^^^
  File "C:\Users\ASUS\anaconda3\envs\gpu_torch_5\Lib\site-packages\wandb\util.py", line 965, in check_retry_fn
    return fallback_retry_fn(e)
           ^^^^^^^^^^^^^^^^^^^^
  File "C:\Users\ASUS\anaconda3\envs\gpu_torch_5\Lib\site-packages\wandb\util.py", line 907, in no_retry_auth
    raise CommError(
wandb.errors.CommError: It appears that you do not have permission to access the requested resource. Please reach out to the project owner to grant you access. If you have the correct permissions, verify that there are no issues with your networking setup.(Error 403: Forbidden)
2025-04-27 15:47:02,076 DEBUG   HandlerThread:22968 [handler.py:handle_request():146] handle_request: shutdown
2025-04-27 15:47:02,076 INFO    HandlerThread:22968 [handler.py:finish():866] shutting down handler
2025-04-27 15:47:02,497 INFO    SenderThread:22968 [sender.py:finish():1548] shutting down sender
2025-04-27 15:47:02,667 INFO    WriterThread:22968 [datastore.py:close():294] close: D:\IIT Delhi\Projects\Adversarial games\Experimentation\codeBase\wandb\run-20250427_154700-juanycn7\run-juanycn7.wandb
